Workbook

Sheet Individual Surfactant Key
A1: Individual Surfactant Key
C2: CAS# | D2: Source | E2: Additional Info
A3: TMN6 | B3: Tergitol TMN6 | D3: Commercial
A4: T15-S-7 | B4: Tergitol 15-S-7 | D4: Commercial
A5: TrX45 | B5: Triton X-45 | D5: Commercial
A6: TrX114 | B6: Triton X-114 | D6: Commercial
A7: LinSucSulf | B7: Linear Succinate Sulfonate | D7: Commercial
A8: T4 | B8: Tergitol 4 (Niaproof 4) | D8: Commercial
A9: TrCG-425 | B9: Triton CG-425 | D9: Commercial
A10: AlfSodSalt | B10: Alfa Sodium Salt | D10: Commercial
A11: AlphaFoam | B11: Alpha Foamer | D11: Commercial
A12: Mys | B12: Myristyl | D12: Commercial
A13: D5575 | B13: Dow 5575 | D13: Commercial
A14: D5244 | B14: Dow 5244 | D14: Commercial
... A42: NRL_N10477-05 | B42: NRL Synthesized trisiloxane tail with 16 PEO units, OH term, NOF precursor | D42: NRL Synthesized
A43: Gel6185 | B43: Gelest SiH 6185 | C43: 67674-67-3 | D43: Commercial | E43: Purchased from Gelest Inc.
A44: G215 | B44: Glucopon 215 UP | D44: Commercial
A45: G225 | B45: Glucopon 225DK | D45: Commercial
A46: G600 | B46: Glucopon 600 UP | D46: Commercial
A47: Gel6492.6 | B47: Gelest SIM 6492.6 | C47: 27306-78-1 | D47: Commercial | E47: Purchased from Gelest Inc.
A48: T15-S-9 | B48: Tergitol 15-S-9 | D48: Commercial
A49: T15-S-12 | B49: Tergitol 15-S-12 | D49: Commercial
A50: CL_C8G3 | B50: China Lake Synthesized APG 8 alkyl chain length with 3 glycoside units | D50: China Lake Synthesized
A51: C6G2 | B51: Anatrace monoglyocisde 6 alkyl carbons long 2 glycoside units | D51: Commercial | E51: Purchased from Anatrace
A52: Buckeye | B52: Commercial AFFF, not an individual surfactant | D52: Commercial
A53: RF6 | B53: Commercial fluorine-free, not an individual surfactant | D53: Commercial
A54: Collab181360 | B54: Experimental material provided by collaborator, structure unknown | D54: Collab Synthesized
A55: C8G2 | B55: Anatrace monoglyocisde 8 alkyl carbons long 2 glycoside units | D55: Commercial | E55: Purchased from Anatrace
A56: C10G2 | B56: Anatrace monoglyocisde 10 alkyl carbons long 2 glycoside units | D56: Commercial | E56: Purchased from Anatrace
A57: C12G2 | B57: Anatrace monoglyocisde 12 alkyl carbons long 2 glycoside units | D57: Commercial | E57: Purchased from Anatrace
A58: C8G1 | B58: Anatrace monoglyocisde 8 alkyl carbons long 1 glycoside units | D58: Commercial | E58: Purchased from Anatrace
A59: Collab_EXP-20-C10628-A | B59: Experimental material provided by collaborater, structure unknown | D59: Collab Synthesized | E59: Tested June 2020
A60: Collab_EXP-20-C10628-B | B60: Experimental material provided by collaborater, structure unknown | D60: Collab Synthesized | E60: Tested June 2020
A61: Collab_EXP-20-C10628-C | B61: Experimental material provided by collaborater, structure unknown | D61: Collab Synthesized | E61: Tested June 2020
A62: Collab_EXP-20-C10628-D | B62: Experimental material provided by collaborater, structure unknown | D62: Collab Synthesized | E62: Tested June 2020
A63: Collab_EXP-20-C10628-E | B63: Experimental material provided by collaborater, structure unknown | D63: Collab Synthesized | E63: Tested June 2020
A64: Collab_EXP-21-1 | B64: Experimental material provided by collaborater, structure unknown | D64: Collab Synthesized | E64: Tested Sept/Oct 2021
A65: Collab_EXP-21-2 | B65: Experimental material provided by collaborater, structure unknown | D65: Collab Synthesized | E65: Tested Sept/Oct 2021
A66: AvioGreen | B66: Commercial fluorine-free made by National Foam, not an individual surfactant | D66: Commercial | E66: Batch number not known, tested 2020/2021
... A87: Collab_EXP-21-CH1035-C | B87: Experimental material provided by collaborater, structure unknown | D87: Collab Synthesized | E87: Tested May 2021
...

Sheet Indiv. Surfactant Key
A1: Individual Surfactant Key | G1: Color code
A2: Short-Hand Notation | B2: Full Name | C2: Source | D2: Additional Info | G2: Surfactant with SMILES
A3: TMN6 | B3: Tergitol TMN6 | C3: Commercial | D3: Purchased from Sigma Aldrich | G3: Commercial Surfactant with no SMILES
A4: T15-S-7 | B4: Tergitol 15-S-7 | C4: Commercial | D4: Purchased from Sigma Aldrich | G4: Commercial firefighting foam concentrate
A5: TrX45 | B5: Triton X-45 | C5: Commercial | D5: Purchased from Sigma Aldrich | G5: Experimental firefighting foam concentrate
A6: TrX114 | B6: Triton X-114 | C6: Commercial | D6: Purchased from Sigma Aldrich
A7: T4 | B7: Tergitol 4 (Niaproof 4) | C7: Commercial | D7: Purchased from Sigma Aldrich
A8: AlfSodSalt | B8: Alfa Sodium Salt | C8: Commercial
A9: Mys | B9: Myristyl | C9: Commercial
A10: D502W | B10: Dow 502W | C10: Commercial | D10: Provided by Dow Chemical
A11: SDS | B11: Sodium dodecyl sulfate | C11: Commercial | D11: Purchased from Sigma Aldrich
A12: TrX100 | B12: Triton X-100 | C12: Commercial | D12: Purchased from Sigma Aldrich
A13: CTAB | B13: Centrimonium bromide | C13: Commercial
A14: Cap | B14: Capstone 1157N | C14: Commercial | D14: Provided by Chemours
A15: L77 | B15: Silwet L77 | C15: Commercial
A16: PFOA | B16: Perfluorooctanoic acid | C16: Commercial
A17: NRL_N10358-107 | B17: trisiloxane tail with no PEO units in head, OH terminated (mondisperse) | C17: NRL Synthesized
A18: NRL_N10358-106 | B18: trisiloxane tail with 1 PEO unit, OH terminated (monodispersed) | C18: NRL Synthesized
A19: NRL_N10358-135 | B19: trisiloxane tail with 3 PEO units, OH terminated (mondispersed) | C19: NRL Synthesized
A20: NRL_N10477-12 | B20: trisiloxane tail with 4-7 PEO units in head, OH terminated | C20: NRL Synthesized
A21: NRL_N10358-176 | B21: trisiloxane tail with 9-12 PEO units in head, OH terminated | C21: NRL Synthesized
A22: NRL_N10358-174 | B22: trisiloxane tail with 12-20 PEO units in head, OH terminated | C22: NRL Synthesized
A23: NRL_N10358-169 | B23: trisiloxane tail with 35-50 PEO units in head, OH terminated | C23: NRL Synthesized
A24: NRL_N10477-01 | B24: trisiloxane tail with 11-12 PEO units, OH terminated | C24: NRL Synthesized
A25: NRL_N10358-161 | B25: trisiloxane tail with 2 PEO units, OH terminated (monodisperse) | C25: NRL Synthesized
A26: NRL_N10477-09 | B26: tetrasilane tail with 11-12 PEO units, OH terminated | C26: NRL Synthesized
... A29: NRL_N10477-05 | B29: trisiloxane tail with 15-16 PEO units, OH terminated | C29: NRL Synthesized
A30: Gel6185 | B30: Gelest SiH 6185 | C30: Commercial | D30: Purchased from Gelest Inc.
A31: G215 | B31: Glucopon 215 UP | C31: Commercial | D31: Purchased from BASF
A32: G225 | B32: Glucopon 225DK | C32: Commercial | D32: Purchased from BASF
A33: G600 | B33: Glucopon 600 UP | C33: Commercial | D33: Purchased from BASF
A34: Gel6492.6 | B34: Gelest SIM 6492.6 | C34: Commercial | D34: Purchased from Gelest Inc.
A35: T15-S-9 | B35: Tergitol 15-S-9 | C35: Commercial | D35: Purchased from Sigma Aldrich
A36: T15-S-12 | B36: Tergitol 15-S-12 | C36: Commercial | D36: Purchased from Sigma Aldrich
A37: CL_C8G3 | B37: APG: 8 alkyl chain length 3 glycoside units | C37: China Lake Synthesized
A38: C8G2 | B38: APG: 8 alkyl chain length 2 glycoside units | C38: Commercial | D38: Purchased from Anatrace
A39: C10G2 | B39: APG: 10 alkyl chain length 2 glycoside units | C39: Commercial | D39: Purchased from Anatrace
A40: C12G2 | B40: APG: 12 alkyl chain length 2 glycoside units | C40: Commercial | D40: Purchased from Anatrace
A41: C8G1 | B41: APG: 8 alkyl chain length 1 glycoside unit | C41: Commercial | D41: Purchased from Anatrace
A42: C8SG2 | B42: APG: 8 alkyl chain length 2 sulfonated substituted glycoside units | C42: Commercial | D42: Purchased from Anatrace
...

Sheet SMILES Individual
A1: SMILES files, highlighted in orange are polydisperse structures with multiple SMILES files (22 structures)
A2: ='Indiv. Surfactant Key'!A8 -> AlfSodSalt | B2: ='Indiv. Surfactant Key'!A39 -> C10G2 | C2: ='Indiv. Surfactant Key'!A40 -> C12G2 | D2: ='Indiv. Surfactant Key'!A62 -> C12G3 | E2: ='Indiv. Surfactant Key'!A47 -> C6G1 | F2: ='Indiv. Surfactant Key'!A45 -> C6G2 | G2: ='Indiv. Surfactant Key'!A48 -> C7G1 | H2: ='Indiv. Surfactant Key'!A41 -> C8G1 | I2: ='Indiv. Surfactant Key'!A38 -> C8G2 | J2: ='Indiv. Surfactant Key'!A42 -> C8SG2 | K2: ='Indiv. Surfactant Key'!A46 -> C9G2 | L2: ='Indiv. Surfactant Key'!A14 -> Cap | M2: ='Indiv. Surfactant Key'!A37 -> CL_C8G3 | N2: ='Indiv. Surfactant Key'!A54 -> CL_MD2012-16 | O2: ='Indiv. Surfactant Key'!A49 -> CL_MD2062-121 | P2: ='Indiv. Surfactant Key'!A50 -> CL_MD2062-124 | Q2: ='Indiv. Surfactant Key'!A58 -> CL_MD2062-148 | R2: ='Indiv. Surfactant Key'!A57 -> CL_MD2062-57 | S2: ='Indiv. Surfactant Key'!A53 -> CL_MD2086-97 | T2: ='Indiv. Surfactant Key'!A59 -> CL_MD2102-54 | U2: ='Indiv. Surfactant Key'!A69 -> CL_MD2102-90 | V2: ='Indiv. Surfactant Key'!A70 -> CL_MD2102-112 | W2: ='Indiv. Surfactant Key'!A71 -> CL_MD2102-118 | X2: ='Indiv. Surfactant Key'!A52 -> CL_MDAPS | Y2: ='Indiv. Surfactant Key'!A13 -> CTAB | Z2: ='Indiv. Surfactant Key'!A43 -> Cymal | AA2: ='Indiv. Surfactant Key'!A44 -> iC8G2 | AB2: ='Indiv. Surfactant Key'!A9 -> Mys | AC2: ='Indiv. Surfactant Key'!A55 -> NRL_CB-1-123 | AD2: ='Indiv. Surfactant Key'!A64 -> NRL_LBII43 | AE2: ='Indiv. Surfactant Key'!A18 -> NRL_N10358-106 | AF2: ='Indiv. Surfactant Key'!A17 -> NRL_N10358-107 | AG2: ='Indiv. Surfactant Key'!A19 -> NRL_N10358-135 | AH2: ='Indiv. Surfactant Key'!A25 -> NRL_N10358-161 | AI2: ='Indiv. Surfactant Key'!A22 -> NRL_N10358-174 | AJ2: ='Indiv. Surfactant Key'!A66 -> NRL_N10478-227 | AK2: ='Indiv. Surfactant Key'!A67 -> NRL_N10478-233 | AL2: ='Indiv. Surfactant Key'!A68 -> NRL_N10478-240 | AM2: ='Indiv. Surfactant Key'!A36 -> T15-S-12 | AN2: ='Indiv. Surfactant Key'!A4 -> T15-S-7 | AO2: ='Indiv. Surfactant Key'!A35 -> T15-S-9 | AP2: ='Indiv. Surfactant Key'!A3 -> TMN6 | AQ2: ='Indiv. Surfactant Key'!A12 -> TrX100 | AR2: ='Indiv. Surfactant Key'!A6 -> TrX114 | AS2: ='Indiv. Surfactant Key'!A5 -> TrX45 | AT2: ='Indiv. Surfactant Key'!A51 -> TrGR-5M | AU2: ='Indiv. Surfactant Key'!A7 -> T4 | AV2: ='Indiv. Surfactant Key'!A16 -> PFOA | AW2: ='Indiv. Surfactant Key'!A11 -> SDS | AX2: ='Indiv. Surfactant Key'!A30 -> Gel6185 | AY2: ='Indiv. Surfactant Key'!A34 -> Gel6492.6 | AZ2: ='Indiv. Surfactant Key'!A31 -> G215 | BA2: ='Indiv. Surfactant Key'!A32 -> G225 | BB2: ='Indiv. Surfactant Key'!A33 -> G600 | BC2: ='Indiv. Surfactant Key'!A15 -> L77 | BD2: ='Indiv. Surfactant Key'!A20 -> NRL_N10477-12 | BE2: ='Indiv. Surfactant Key'!A21 -> NRL_N10358-176 | BF2: ='Indiv. Surfactant Key'!A23 -> NRL_N10358-169 | BG2: ='Indiv. Surfactant Key'!A24 -> NRL_N10477-01 | BH2: ='Indiv. Surfactant Key'!A26 -> NRL_N10477-09 | BI2: ='Indiv. Surfactant Key'!A27 -> NRL_N10477-07 | BJ2: ='Indiv. Surfactant Key'!A28 -> NRL_N10477-03 | BK2: ='Indiv. Surfactant Key'!A29 -> NRL_N10477-05 | BL2: ='Indiv. Surfactant Key'!A56 -> NRL_N10477-189 | BM2: ='Indiv. Surfactant Key'!A60 -> NRL_N10478-198 | BN2: ='Indiv. Surfactant Key'!A61 -> C10G3 | BO2: ='Indiv. Surfactant Key'!A63 -> NRL_N10478-40 | BP2: ='Indiv. Surfactant Key'!A65 -> NRL_CB_DTBTS_SB | BQ2: ='Indiv. Surfactant Key'!A72 -> NRL_CB-1-192 | BR2: ='Indiv. Surfactant Key'!A10 -> D502W | BS2: ='Indiv. Surfactant Key'!A73 -> NRL_N10478-81 | BT2: DGBE
A3: CC(C)CC(C)OC(=O)CC(C(=O)OC(C)CC(C)C)S(=O)(=O)[O-].[Na+] | B3: CCCCCCCCCCO[C@H]1[C@@H]([C@H]([C@@H]([C@H](O1)CO)O[C@@H]2[C@@H]([C@H]([C@@H]([C@H](O2)CO)O)O)O)O)O | C3: CCCCCCCCCCCCO[C@H]1[C@@H]([C@H]([C@@H]([C@H](O1)CO)O[C@@H]2[C@@H]([C@H]([C@@H]([C@H](O2)CO)O)O)O)O)O | D3: CCCCCCCCCCCCO[C@@H]3O[C@H](CO)C(O[C@H]2O[C@H](CO)C(O[C@H]1O[C@H](CO)[C@@H](O)[C@H](O)[C@H]1O)[C@H](O)[C@H]2O)[C@H](O)[C@H]3O | E3: CCCCCCO[C@H]1[C@@H]([C@H]([C@@H]([C@H](O1)CO)O)O)O | F3: CCCCCCO[C@@H]1O[C@H](CO)[C@H](O[C@H]2O[C@H](CO)[C@@H](O)[C@H](O)[C@H]2O)[C@H](O)[C@H]1O | G3: CCCCCCCO[C@H]1[C@@H]([C@H]([C@@H]([C@H](O1)CO)O)O)O | H3: CCCCCCCCO[C@@H]1O[C@H](CO)[C@@H](O)[C@H](O)[C@H]1O | I3: CCCCCCCCO[C@H]1[C@@H]([C@H]([C@@H]([C@H](O1)CO)O[C@@H]2[C@@H]([C@H]([C@@H]([C@H](O2)CO)O)O)O)O)O | J3: CCCCCCCCS[C@@H]1O[C@H](CO)[C@@H](O[C@H]2O[C@H](CO)[C@@H](O)[C@H](O)[C@H]2O)[C@H](O)[C@H]1O | K3: CCCCCCCCCO[C@@H]1O[C@H](CO)[C@@H](O[C@H]2O[C@H](CO)[C@@H](O)[C@H](O)[C@H]2O)[C@H](O)[C@H]1O | L3: C[N+](C)(CCN[S](=O)(=O)CCC(F)(F)C(F)(F)C(F)(F)C(F)(F)C(F)(F)C(F)(F)F)CC([O-])=O | M3: CCCCCCCCO[C@@H]3O[C@H](CO)C(O[C@H]2O[C@H](CO)C(O[C@H]1O[C@H](CO)[C@@H](O)[C@H](O)[C@H]1O)[C@H](O)[C@H]2O)[C@H](O)[C@H]3O | N3: C[N+](C)(CCC[Si](C)(O[Si](C)(C)C)O[Si](C)(C)C)CCCS(=O)(=O)[O-] | O3: C[Si](C)(C)O[Si](C)(CCCNC([C@@H](O)[C@H](O)[C@@H](O)[C@@H](O)CO)=O)O[Si](C)(C)C | P3: C[Si](C)(C)O[Si](O[Si](C)(C)C)(CCC[N+](C)(CCCS(=O)([O-])=O)C)O[Si](C)(C)C | Q3: C[Si](C)(C)O[Si](CCC[n+]1ccccc1)(O[Si](C)(C)C)O[Si](C)(C)C.[Cl-] | R3: C[N+](C)(C)CCC[Si](O[Si](C)(C)C)(O[Si](C)(C)C)O[Si](C)(C)C.[I-] | S3: C[Si](C)(C)O[Si](O[Si](C)(C)C)(CCCNCCNC(C(O)C(O)C(O)C(O)CO)=O)O[Si](C)(C)C | T3: C[Si](C)(C)O[Si](C)(CCCOC2OC(CO)C(OC1OC(CO)C(O)C(O)C1O)C(O)C2O)O[Si](C)(C)C | U3: [O-]S(CCC[N+](C)(C)CCC[Si](C)(C)C[Si](C)(C)C)(=O)=O | V3: C[Si](C)(C)O[Si](O[Si](C)(C)C)(O[Si](C)(C)C)CCCOC1C(O)C(O)C(OC2C(O)C(O)C(O)C(CO)O2)C(CO)O1 | W3: C[Si](C)(C)O[Si](O[Si](C)(C)C)(O[Si](C)(C)C)CCCNC(C(O)C(O)C(OC1C(O)C(O)C(O)C(CO)O1)C(O)CO)=O | X3: C[Si](C)(C)O[Si](C)(CCCN)O[Si](C)(C)C | Y3: CCCCCCCCCCCCCCCC[N+](C)(C)C.[Br-] | Z3: OC[C@H]1O[C@H](O[C@H]2[C@H](O)[C@@H](O)[C@H](OCCCCCC3CCCCC3)O[C@@H]2CO)[C@H](O)[C@@H](O)[C@@H]1O | AA3: CCCC(CCC)CO[C@H]1[C@@H]([C@H]([C@@H]([C@H](O1)CO)O[C@@H]2[C@@H]([C@H]([C@@H]([C@H](O2)CO)O)O)O)O)O | AB3: CCCCCCCCCCCCCC[N+](C)(C)CCCS([O-])(=O)=O | AC3: C[N+](C)(CCCCS(=O)(=O)[O-])CCC[Si](C)(O[Si](C)(C)C)O[Si](C)(C)C | AD3: COCCOCCOCCOCCOCCOCCOCCOCCOCCOCCC[Si](C)(O[Si](C)(C)C)O[Si](C)(C)C | AE3: C[Si](O[Si](C)(C)C)(CCCOCCO)O[Si](C)(C)C | AF3: C[Si](O[Si](C)(C)C)(CCCO)O[Si](C)(C)C | AG3: C[Si](O[Si](C)(C)C)(CCCOCCOCCOCCO[H])O[Si](C)(C)C | AH3: C[Si](O[Si](C)(C)C)(CCCOCCOCCO[H])O[Si](C)(C)C | AI3: C[Si](O[Si](C)(C)C)(CCCOCCOCCOCCOCCOCCOCCOCCOCCOCCOCCOCCOCCO[H])O[Si](C)(C)C | AJ3: C[Si](C)(C)O[Si](O[Si](C)(C)C)(C)CCCOCC(O)CNC(CO)(CO)CO | AK3: C[Si](C)(C)O[Si](O[Si](C)(C)C)(C)CCCOCC(O)CN(CCO)CCO | AL3: C[Si](C)(C)O[Si](O[Si](C)(C)C)(C)CCCNC(C(O)C(O)C(O)C(O)CO)=O | AM3: CCCCCCCC(CCCCC)OCCOCCOCCOCCOCCOCCOCCOCCOCCOCCOCCOCCO | AN3: CCCCCCCC(CCCCC)OCCOCCOCCOCCOCCOCCOCCO | AO3: CCCCCCCC(CCCCC)OCCOCCOCCOCCOCCOCCOCCOCCOCCO | AP3: CC(C)CC(C)CC(CC(C)C)OCCOCCOCCOCCOCCOCCO | AQ3: CC(C)(C)CC(C)(C)C1=CC=C(C=C1)OCCOCCOCCOCCOCCOCCOCCOCCOCCO | AR3: CC(C)(C)CC(C)(C)C1=CC=C(C=C1)OCCOCCOCCOCCOCCOCCOCCO | AS3: CC(C)(C)CC(C)(C)C1=CC=C(C=C1)OCCOCCOCCOCCOCCO | AT3: [Na+].CCCCC(CC)COC(=O)CC(C(=O)OCC(CC)CCCC)S(=O)(=O)[O-] | AU3: [Na+].CCCCC(CC)CCC(CC(C)C)OS([O-])(=O)=O | AV3: FC(F)(C(F)(F)C(=O)O)C(F)(F)C(F)(F)C(F)(F)C(F)(F)C(F)(F)F | AW3: CCCCCCCCCCCCOS(=O)([O-])=O.[Na+] | AX3: C[Si](C)(C)O[Si](C)(CCCOCCOCCOCCOCCOCCOCCO)O[Si](C)(C)C | AY3: COCCOCCOCCOCCOCCOCCOCCC[Si](C)(O[Si](C)(C)C)O[Si](C)(C)C | AZ3: CCCCCCCCO[C@@H]1O[C@H](CO)[C@@H](O)[C@H](O)[C@H]1O | BA3: CCCCCCCCO[C@@H]1O[C@H](CO)[C@@H](O)[C@H](O)[C@H]1O | BB3: CCCCCCCCCOC1C(C(C(C(O1)CO)O)O)O | BC3: COCCOCCOCCOCCOCCC[Si](C)(O[Si](C)(C)C)O[Si](C)(C)C | BD3: C[Si](O[Si](C)(C)C)(CCCOCCOCCOCCOCCO[H])O[Si](C)(C)C | BE3: C[Si](O[Si](C)(C)C)(CCCOCCOCCOCCOCCOCCOCCOCCOCCOCCO[H])O[Si](C)(C)C | BF3: C[Si](O[Si](C)(C)C)(CCCOCCOCCOCCOCCOCCOCCOCCOCCOCCOCCOCCOCCOCCOCCOCCOCCOCCOCCOCCOCCOCCOCCOCCOCCOCCOCCOCCOCCOCCOCCOCCOCCOCCOCCOCCO[H])O[Si](C)(C)C | BG3: C[Si](O[Si](C)(C)C)(CCCOCCOCCOCCOCCOCCOCCOCCOCCOCCOCCOCCOCCO[H])O[Si](C)(C)C | BH3: [H]OCCOCCOCCOCCOCCOCCOCCOCCOCCOCCOCCOCCC[Si]([Si](C)(C)C)([Si](C)(C)C)[Si](C)(C)C | BI3: C[Si](O[Si](C)(C)C)(CCCOCCOCCOCCOCCOCCOCCOCCOCCO[H])O[Si](C)(C)C | BJ3: C[Si](O[Si](C)(C)C)(CCCOCCOCCOCCOCCOCCOCCOCCOCCO[H])O[Si](C)(C)C | BK3: C[Si](O[Si](C)(C)C)(CCCOCCOCCOCCOCCOCCOCCOCCOCCOCCOCCOCCOCCOCCOCCOCCO[H])O[Si](C)(C)C | BL3: C[N+](C)(CCCS(=O)([O-])=O)CCC[Si]([Si](C)(C)C)([Si](C)(C)C)[Si](C)(C)C | BM3: C[Si](C)(C)O[Si](O[Si](C)(C)C)(CCC[N+](C)(CCCS(=O)([O-])=O)C)O[Si](C)(C)C | BN3: CCCCCCCCCCO[C@@H]3O[C@H](CO)C(O[C@H]2O[C@H](CO)C(O[C@H]1O[C@H](CO)[C@@H](O)[C@H](O)[C@H]1O)[C@H](O)[C@H]2O)[C@H](O)[C@H]3O | BO3: C[N+](C)(CCC[Si](C)(O[Si](C)(C)C)O[Si](C)(C)C)CCCS(=O)(=O)[O-] | BP3: C[Si](C[Si](C)(C)C(C)(C)C)(CCC[N+](C)(C)CCCS([O-])(=O)=O)C[Si](C)(C(C)(C)C)C | BQ3: C[Si](O[Si](C)(CCl)C)(CCCOCCOCCOCCOCCOCCOCCOCCOCCOCCOCCOC)O[Si](C)(CCl)C | BR3: C[Si](C)(C)O[Si](C)(CCCOCCOCCOCCOCCOCCOCCOCCOCCOCCOCCOCCOCCOCCOCCOCCO)O[Si](C)(C)C | BS3: C[N+](C)(CCC[Si]1(C)O[Si](C)(C)O[Si](C)(C)O[Si](C)(C)O1)CCCS(=O)(=O)[O-] | BT3: CCCCOCCOCCO
AD4: COCCOCCOCCOCCOCCOCCOCCOCCOCCOCCOCCC[Si](C)(O[Si](C)(C)C)O[Si](C)(C)C | AI4: C[Si](O[Si](C)(C)C)(CCCOCCOCCOCCOCCOCCOCCOCCOCCOCCOCCOCCOCCOCCO[H])O[Si](C)(C)C | AM4: CCCCCCCCC(CCCCCC)OCCOCCOCCOCCOCCOCCOCCOCCOCCOCCOCCOCCO | AN4: CCCCCCCCC(CCCCCC)OCCOCCOCCOCCOCCOCCOCCO | AO4: CCCCCCCCC(CCCCCC)OCCOCCOCCOCCOCCOCCOCCOCCOCCO | AQ4: CC(C)(C)CC(C)(C)C1=CC=C(C=C1)OCCOCCOCCOCCOCCOCCOCCOCCOCCOCCO | AR4: CC(C)(C)CC(C)(C)C1=CC=C(C=C1)OCCOCCOCCOCCOCCOCCOCCOCCO | AS4: CC(C)(C)CC(C)(C)C1=CC=C(C=C1)OCCOCCOCCOCCO | AX4: C[Si](C)(C)O[Si](C)(CCCOCCOCCOCCOCCOCCOCCOCCO)O[Si](C)(C)C | AY4: COCCOCCOCCOCCOCCOCCOCCOCCC[Si](C)(O[Si](C)(C)C)O[Si](C)(C)C | AZ4: OC[C@H]1O[C@@H](OCCCCCCCCC)[C@H](O)[C@@H](O)[C@@H]1O | BA4: OC[C@H]1O[C@@H](OCCCCCCCCC)[C@H](O)[C@@H](O)[C@@H]1O | BB4: CCCCCCCCCCOC1C(C(C(C(O1)CO)O)O)O | BC4: COCCOCCOCCOCCOCCOCCC[Si](C)(O[Si](C)(C)C)O[Si](C)(C)C | BD4: C[Si](O[Si](C)(C)C)(CCCOCCOCCOCCOCCOCCO[H])O[Si](C)(C)C | BE4: C[Si](O[Si](C)(C)C)(CCCOCCOCCOCCOCCOCCOCCOCCOCCOCCOCCO[H])O[Si](C)(C)C | BF4: C[Si](O[Si](C)(C)C)(CCCOCCOCCOCCOCCOCCOCCOCCOCCOCCOCCOCCOCCOCCOCCOCCOCCOCCOCCOCCOCCOCCOCCOCCOCCOCCOCCOCCOCCOCCOCCOCCOCCOCCOCCOCCOCCO[H])O[Si](C)(C)C | BH4: [H]OCCOCCOCCOCCOCCOCCOCCOCCOCCOCCOCCOCCOCCC[Si]([Si](C)(C)C)([Si](C)(C)C)[Si](C)(C)C | BJ4: C[Si](O[Si](C)(C)C)(CCCOCCOCCOCCOCCOCCOCCOCCOCCOCCO[H])O[Si](C)(C)C | BK4: C[Si](O[Si](C)(C)C)(CCCOCCOCCOCCOCCOCCOCCOCCOCCOCCOCCOCCOCCOCCOCCOCCOCCO[H])O[Si](C)(C)C | BQ4: C[Si](O[Si](C)(CCl)C)(CCCOCCOCCOCCOCCOCCOCCOCCOCCOCCOCCOCCOC)O[Si](C)(CCl)C | BR4: C[Si](C)(C)O[Si](C)(CCCOCCOCCOCCOCCOCCOCCOCCOCCOCCOCCOCCOCCOCCOCCO)O[Si](C)(C)C
AD5: COCCOCCOCCOCCOCCOCCOCCOCCOCCOCCOCCOCCC[Si](C)(O[Si](C)(C)C)O[Si](C)(C)C | AI5: C[Si](O[Si](C)(C)C)(CCCOCCOCCOCCOCCOCCOCCOCCOCCOCCOCCOCCOCCOCCOCCO[H])O[Si](C)(C)C | AX5: C[Si](C)(C)O[Si](C)(CCCOCCOCCOCCOCCOCCOCCOCCOCCO)O[Si](C)(C)C | AY5: COCCOCCOCCOCCOCCOCCOCCOCCOCCC[Si](C)(O[Si](C)(C)C)O[Si](C)(C)C | AZ5: CCCCCCCCCCOC1[C@@H]([C@H]([C@@H]([C@H](O1)CO)O)O)O | BA5: CCCCCCCCCCOC1[C@@H]([C@H]([C@@H]([C@H](O1)CO)O)O)O | BB5: CCCCCCCCCCCOC1C(C(C(C(O1)CO)O)O)O | BC5: COCCOCCOCCOCCOCCOCCOCCC[Si](C)(O[Si](C)(C)C)O[Si](C)(C)C | BD5: C[Si](O[Si](C)(C)C)(CCCOCCOCCOCCOCCOCCOCCO[H])O[Si](C)(C)C | BE5: C[Si](O[Si](C)(C)C)(CCCOCCOCCOCCOCCOCCOCCOCCOCCOCCOCCOCCO[H])O[Si](C)(C)C | BF5: C[Si](O[Si](C)(C)C)(CCCOCCOCCOCCOCCOCCOCCOCCOCCOCCOCCOCCOCCOCCOCCOCCOCCOCCOCCOCCOCCOCCOCCOCCOCCOCCOCCOCCOCCOCCOCCOCCOCCOCCOCCOCCOCCOCCO[H])O[Si](C)(C)C | BQ5: C[Si](O[Si](C)(CCl)C)(CCCOCCOCCOCCOCCOCCOCCOCCOCCOCCOCCOCCOCCOC)O[Si](C)(CCl)C | BR5: C[Si](C)(C)O[Si](C)(CCCOCCOCCOCCOCCOCCOCCOCCOCCOCCOCCOCCOCCOCCO)O[Si](C)(C)C
AD6: COCCOCCOCCOCCOCCOCCOCCOCCOCCOCCOCCOCCOCCC[Si](C)(O[Si](C)(C)C)O[Si](C)(C)C | AI6: C[Si](O[Si](C)(C)C)(CCCOCCOCCOCCOCCOCCOCCOCCOCCOCCOCCOCCOCCOCCOCCOCCO[H])O[Si](C)(C)C | AX6: C[Si](C)(C)O[Si](C)(CCCOCCOCCOCCOCCOCCOCCOCCOCCOCCO)O[Si](C)(C)C | AY6: COCCOCCOCCOCCOCCOCCOCCOCCOCCOCCC[Si](C)(O[Si](C)(C)C)O[Si](C)(C)C | AZ6: CCCCCCCCO[C@H]1[C@@H]([C@H]([C@@H]([C@H](O1)CO)O[C@@H]2[C@@H]([C@H]([C@@H]([C@H](O2)CO)O)O)O)O)O | BA6: CCCCCCCCO[C@H]1[C@@H]([C@H]([C@@H]([C@H](O1)CO)O[C@@H]2[C@@H]([C@H]([C@@H]([C@H](O2)CO)O)O)O)O)O | BB6: CCCCCCCCCCCCOC1C(C(C(C(O1)CO)O)O)O | BC6: COCCOCCOCCOCCOCCOCCOCCOCCC[Si](C)(O[Si](C)(C)C)O[Si](C)(C)C | BD6: C[Si](O[Si](C)(C)C)(CCCOCCOCCOCCOCCOCCOCCOCCO[H])O[Si](C)(C)C | BE6: C[Si](O[Si](C)(C)C)(CCCOCCOCCOCCOCCOCCOCCOCCOCCOCCOCCOCCOCCO[H])O[Si](C)(C)C | BF6: C[Si](O[Si](C)(C)C)(CCCOCCOCCOCCOCCOCCOCCOCCOCCOCCOCCOCCOCCOCCOCCOCCOCCOCCOCCOCCOCCOCCOCCOCCOCCOCCOCCOCCOCCOCCOCCOCCOCCOCCOCCOCCOCCOCCOCCO[H])O[Si](C)(C)C | BQ6: C[Si](O[Si](C)(CCl)C)(CCCOCCOCCOCCOCCOCCOCCOCCOCCOCCOCCOCCOCCOCCOC)O[Si](C)(CCl)C | BR6: C[Si](C)(C)O[Si](C)(CCCOCCOCCOCCOCCOCCOCCOCCOCCOCCOCCOCCOCCO)O[Si](C)(C)C
AD7: COCCOCCOCCOCCOCCOCCOCCOCCOCCOCCOCCOCCOCCOCCC[Si](C)(O[Si](C)(C)C)O[Si](C)(C)C | AI7: C[Si](O[Si](C)(C)C)(CCCOCCOCCOCCOCCOCCOCCOCCOCCOCCOCCOCCOCCOCCOCCOCCOCCO[H])O[Si](C)(C)C | AZ7: CCCCCCCCCO[C@@H]1O[C@H](CO)[C@@H](O[C@H]2O[C@H](CO)[C@@H](O)[C@H](O)[C@H]2O)[C@H](O)[C@H]1O | BA7: CCCCCCCCCO[C@@H]1O[C@H](CO)[C@@H](O[C@H]2O[C@H](CO)[C@@H](O)[C@H](O)[C@H]2O)[C@H](O)[C@H]1O | BB7: CCCCCCCCCCCCCOC1C(C(C(C(O1)CO)O)O)O | BC7: COCCOCCOCCOCCOCCOCCOCCOCCOCCC[Si](C)(O[Si](C)(C)C)O[Si](C)(C)C | BF7: C[Si](O[Si](C)(C)C)(CCCOCCOCCOCCOCCOCCOCCOCCOCCOCCOCCOCCOCCOCCOCCOCCOCCOCCOCCOCCOCCOCCOCCOCCOCCOCCOCCOCCOCCOCCOCCOCCOCCOCCOCCOCCOCCOCCOCCOCCO[H])O[Si](C)(C)C | BQ7: C[Si](O[Si](C)(CCl)C)(CCCOCCOCCOCCOCCOCCOCCOCCOCCOCCOCCOCCOCCOCCOCCOC)O[Si](C)(CCl)C | BR7: C[Si](C)(C)O[Si](C)(CCCOCCOCCOCCOCCOCCOCCOCCOCCOCCOCCOCCO)O[Si](C)(C)C
AD8: COCCOCCOCCOCCOCCOCCOCCOCCOCCOCCOCCOCCOCCOCCOCCC[Si](C)(O[Si](C)(C)C)O[Si](C)(C)C | AI8: C[Si](O[Si](C)(C)C)(CCCOCCOCCOCCOCCOCCOCCOCCOCCOCCOCCOCCOCCOCCOCCOCCOCCOCCO[H])O[Si](C)(C)C | AZ8: CCCCCCCCCCO[C@H]1[C@@H]([C@H]([C@@H]([C@H](O1)CO)O[C@@H]2[C@@H]([C@H]([C@@H]([C@H](O2)CO)O)O)O)O)O | BA8: CCCCCCCCCCO[C@H]1[C@@H]([C@H]([C@@H]([C@H](O1)CO)O[C@@H]2[C@@H]([C@H]([C@@H]([C@H](O2)CO)O)O)O)O)O | BB8: CCCCCCCCCCCCCCOC1C(C(C(C(O1)CO)O)O)O | BC8: COCCOCCOCCOCCOCCOCCOCCOCCOCCOCCC[Si](C)(O[Si](C)(C)C)O[Si](C)(C)C | BF8: C[Si](O[Si](C)(C)C)(CCCOCCOCCOCCOCCOCCOCCOCCOCCOCCOCCOCCOCCOCCOCCOCCOCCOCCOCCOCCOCCOCCOCCOCCOCCOCCOCCOCCOCCOCCOCCOCCOCCOCCOCCOCCOCCOCCOCCOCCOCCO[H])O[Si](C)(C)C | BQ8: C[Si](O[Si](C)(CCl)C)(CCCOCCOCCOCCOCCOCCOCCOCCOCCOCCOCCOCCOCCOCCOCCOCCOC)O[Si](C)(CCl)C | BR8: C[Si](C)(C)O[Si](C)(CCCOCCOCCOCCOCCOCCOCCOCCOCCOCCOCCO)O[Si](C)(C)C
AI9: C[Si](O[Si](C)(C)C)(CCCOCCOCCOCCOCCOCCOCCOCCOCCOCCOCCOCCOCCOCCOCCOCCOCCOCCOCCO[H])O[Si](C)(C)C | BB9: CCCCCCCCCCCCCCCOC1C(C(C(C(O1)CO)O)O)O | BC9: COCCOCCOCCOCCOCCOCCOCCOCCOCCOCCOCCC[Si](C)(O[Si](C)(C)C)O[Si](C)(C)C | BF9: C[Si](O[Si](C)(C)C)(CCCOCCOCCOCCOCCOCCOCCOCCOCCOCCOCCOCCOCCOCCOCCOCCOCCOCCOCCOCCOCCOCCOCCOCCOCCOCCOCCOCCOCCOCCOCCOCCOCCOCCOCCOCCOCCOCCOCCOCCOCCOCCO[H])O[Si](C)(C)C | BR9: C[Si](C)(C)O[Si](C)(CCCOCCOCCOCCOCCOCCOCCOCCOCCOCCO)O[Si](C)(C)C
AI10: C[Si](O[Si](C)(C)C)(CCCOCCOCCOCCOCCOCCOCCOCCOCCOCCOCCOCCOCCOCCOCCOCCOCCOCCOCCOCCO[H])O[Si](C)(C)C | BB10: CCCCCCCCCO[C@H]1[C@@H]([C@H]([C@@H]([C@H](O1)CO)O[C@@H]2[C@@H]([C@H]([C@@H]([C@H](O2)CO)O)O)O)O)O | BC10: COCCOCCOCCOCCOCCOCCOCCOCCOCCOCCOCCOCCC[Si](C)(O[Si](C)(C)C)O[Si](C)(C)C | BF10: C[Si](O[Si](C)(C)C)(CCCOCCOCCOCCOCCOCCOCCOCCOCCOCCOCCOCCOCCOCCOCCOCCOCCOCCOCCOCCOCCOCCOCCOCCOCCOCCOCCOCCOCCOCCOCCOCCOCCOCCOCCOCCOCCOCCOCCOCCOCCOCCOCCO[H])O[Si](C)(C)C
BB11: CCCCCCCCCCO[C@H]1[C@@H]([C@H]([C@@H]([C@H](O1)CO)O[C@@H]2[C@@H]([C@H]([C@@H]([C@H](O2)CO)O)O)O)O)O | BC11: COCCOCCOCCOCCOCCOCCOCCOCCOCCOCCOCCOCCOCCC[Si](C)(O[Si](C)(C)C)O[Si](C)(C)C | BF11: C[Si](O[Si](C)(C)C)(CCCOCCOCCOCCOCCOCCOCCOCCOCCOCCOCCOCCOCCOCCOCCOCCOCCOCCOCCOCCOCCOCCOCCOCCOCCOCCOCCOCCOCCOCCOCCOCCOCCOCCOCCOCCOCCOCCOCCOCCOCCOCCOCCOCCO[H])O[Si](C)(C)C
BB12: CCCCCCCCCCCO[C@H]1[C@@H]([C@H]([C@@H]([C@H](O1)CO)O[C@@H]2[C@@H]([C@H]([C@@H]([C@H](O2)CO)O)O)O)O)O | BF12: C[Si](O[Si](C)(C)C)(CCCOCCOCCOCCOCCOCCOCCOCCOCCOCCOCCOCCOCCOCCOCCOCCOCCOCCOCCOCCOCCOCCOCCOCCOCCOCCOCCOCCOCCOCCOCCOCCOCCOCCOCCOCCOCCOCCOCCOCCOCCOCCOCCOCCOCCO[H])O[Si](C)(C)C
BB13: CCCCCCCCCCCCO[C@H]1[C@@H]([C@H]([C@@H]([C@H](O1)CO)O[C@@H]2[C@@H]([C@H]([C@@H]([C@H](O2)CO)O)O)O)O)O | BF13: C[Si](O[Si](C)(C)C)(CCCOCCOCCOCCOCCOCCOCCOCCOCCOCCOCCOCCOCCOCCOCCOCCOCCOCCOCCOCCOCCOCCOCCOCCOCCOCCOCCOCCOCCOCCOCCOCCOCCOCCOCCOCCOCCOCCOCCOCCOCCOCCOCCOCCOCCOCCO[H])O[Si](C)(C)C
BB14: CCCCCCCCCCCCCO[C@H]1[C@@H]([C@H]([C@@H]([C@H](O1)CO)O[C@@H]2[C@@H]([C@H]([C@@H]([C@H](O2)CO)O)O)O)O)O | BF14: C[Si](O[Si](C)(C)C)(CCCOCCOCCOCCOCCOCCOCCOCCOCCOCCOCCOCCOCCOCCOCCOCCOCCOCCOCCOCCOCCOCCOCCOCCOCCOCCOCCOCCOCCOCCOCCOCCOCCOCCOCCOCCOCCOCCOCCOCCOCCOCCOCCOCCOCCOCCOCCO[H])O[Si](C)(C)C
BB15: CCCCCCCCCCCCCCO[C@H]1[C@@H]([C@H]([C@@H]([C@H](O1)CO)O[C@@H]2[C@@H]([C@H]([C@@H]([C@H](O2)CO)O)O)O)O)O | BF15: C[Si](O[Si](C)(C)C)(CCCOCCOCCOCCOCCOCCOCCOCCOCCOCCOCCOCCOCCOCCOCCOCCOCCOCCOCCOCCOCCOCCOCCOCCOCCOCCOCCOCCOCCOCCOCCOCCOCCOCCOCCOCCOCCOCCOCCOCCOCCOCCOCCOCCOCCOCCOCCOCCO[H])O[Si](C)(C)C
BB16: CCCCCCCCCCCCCCCO[C@H]1[C@@H]([C@H]([C@@H]([C@H](O1)CO)O[C@@H]2[C@@H]([C@H]([C@@H]([C@H](O2)CO)O)O)O)O)O | BF16: C[Si](O[Si](C)(C)C)(CCCOCCOCCOCCOCCOCCOCCOCCOCCOCCOCCOCCOCCOCCOCCOCCOCCOCCOCCOCCOCCOCCOCCOCCOCCOCCOCCOCCOCCOCCOCCOCCOCCOCCOCCOCCOCCOCCOCCOCCOCCOCCOCCOCCOCCOCCOCCOCCOCCO[H])O[Si](C)(C)C
BF17: C[Si](O[Si](C)(C)C)(CCCOCCOCCOCCOCCOCCOCCOCCOCCOCCOCCOCCOCCOCCOCCOCCOCCOCCOCCOCCOCCOCCOCCOCCOCCOCCOCCOCCOCCOCCOCCOCCOCCOCCOCCOCCOCCOCCOCCOCCOCCOCCOCCOCCOCCOCCOCCOCCOCCOCCO[H])O[Si](C)(C)C
BF18: C[Si](O[Si](C)(C)C)(CCCOCCOCCOCCOCCOCCOCCOCCOCCOCCOCCOCCOCCOCCOCCOCCOCCOCCOCCOCCOCCOCCOCCOCCOCCOCCOCCOCCOCCOCCOCCOCCOCCOCCOCCOCCOCCOCCOCCOCCOCCOCCOCCOCCOCCOCCOCCOCCOCCOCCOCCO[H])O[Si](C)(C)C

Sheet Formulation Names Mix CMC Data
A1: Key for CMC - CMC is measured over a range of concentrations, so labels refer to individual surfactants or formulations, do not include specific concentrations
A2: *For CMC data, numbers after nomenclature refer to ratio, not concentrations at which the mixtures were made, all mixtures made with 35 uL DGBE added to initial vial
C3: Detailed description example:
A4: ='Indiv. Surfactant Key'!A3&"_G215_3_2" -> TMN6_G215_3_2 | C4: 3:2 by weight mixture Tergitol TMN6 and Glucopon 215UP
A5: ='Indiv. Surfactant Key'!A4&"_G215_3_2" -> T15-S-7_G215_3_2
A6: ='Individual Surfactant Key'!A5&"_G215_3_2" -> TrX45_G215_3_2
A7: ='Indiv. Surfactant Key'!A6&"_G215_3_2" -> TrX114_G215_3_2
A8: ='Indiv. Surfactant Key'!A74&"_G215_3_2" -> LinSucSulf_G215_3_2
A9: ='Indiv. Surfactant Key'!A7&"_G215_3_2" -> T4_G215_3_2
A10: ='Indiv. Surfactant Key'!A75&"_G215_3_2" -> TrCG-425_G215_3_2
A11: ='Indiv. Surfactant Key'!A8&"_G215_3_2" -> AlfSodSalt_G215_3_2
A12: ='Indiv. Surfactant Key'!A76&"_G215_3_2" -> AlphaFoam_G215_3_2
A13: ='Indiv. Surfactant Key'!A9&"_G215_3_2" -> Mys_G215_3_2
A14: ='Indiv. Surfactant Key'!A77&"_G215_3_2" -> D5575_G215_3_2
A15: ='Indiv. Surfactant Key'!A78&"_G215_3_2" -> D5244_G215_3_2
A16: ='Indiv. Surfactant Key'!A79&"_G215_3_2" -> D193_G215_3_2
A17: ='Indiv. Surfactant Key'!A80&"_G215_3_2" -> D501W_G215_3_2
A18: ='Indiv. Surfactant Key'!A81&"_G215_3_2" -> D198_G215_3_2
A19: ='Indiv. Surfactant Key'!A82&"_G215_3_2" -> D5604_G215_3_2
A20: ='Indiv. Surfactant Key'!A10&"_G215_3_2" -> D502W_G215_3_2
A21: ='Indiv. Surfactant Key'!A83&"_G215_3_2" -> D5098_G215_3_2
A22: ='Indiv. Surfactant Key'!A11&"_G215_3_2" -> SDS_G215_3_2
A23: ='Indiv. Surfactant Key'!A12&"_G215_3_2" -> TrX100_G215_3_2
A24: ='Indiv. Surfactant Key'!A84&"_G215_3_2" -> Silphos_G215_3_2
A25: ='Indiv. Surfactant Key'!A15&"_G215_3_2" -> L77_G215_3_2
A26: ='Indiv. Surfactant Key'!A10&"_TrX100_3_2" -> D502W_TrX100_3_2
A27: ='Indiv. Surfactant Key'!A86&"_G215_3_2" -> D67_G215_3_2
A28: ='Indiv. Surfactant Key'!A10&"_G215_2_3" -> D502W_G215_2_3
A29: ='Indiv. Surfactant Key'!A10&"_G225_2_3" -> D502W_G225_2_3
A30: ='Indiv. Surfactant Key'!A10&"_G600_2_3" -> D502W_G600_2_3
A31: ='Indiv. Surfactant Key'!A34&"_G215_3_2" -> Gel6492.6_G215_3_2
A32: ='Indiv. Surfactant Key'!A35&"_G215_3_2" -> T15-S-9_G215_3_2
A33: ='Indiv. Surfactant Key'!A36&"_G215_3_2" -> T15-S-12_G215_3_2
A34: ='Indiv. Surfactant Key'!A15&"_G225_2_3" -> L77_G225_2_3
A35: ='Indiv. Surfactant Key'!A86&"_G225_2_3" -> D67_G225_2_3
A36: ='Indiv. Surfactant Key'!A10&"_"&'Indiv. Surfactant Key'!A45&"_1_1" -> D502W_C6G2_1_1
A37: ='Indiv. Surfactant Key'!A30&"_G215_3_2" -> Gel6185_G215_3_2
A38: ='Indiv. Surfactant Key'!A14&"_DGBE" -> Cap_DGBE | C38: Capstone Surfactant with 35 uL solvent DGBE in initial vial
A39: ='Indiv. Surfactant Key'!A32&"_DGBE" -> G225_DGBE | C39: Glucopon 225DK Surfactant with 35 uL solvent DGBE in initial vial
A40: ='Indiv. Surfactant Key'!A33&"_DGBE" -> G600_DGBE | C40: Glucopon 600 UP Surfactant with 35 uL solvent DGBE in initial vial
...

Sheet Formulation Name Data
A1: Key for concentration specific data
A2: For this data, numbers after nomenclature refer to wt% of material in solution
A4: ='Indiv. Surfactant Key'!A14&"_"&'Indiv. Surfactant Key'!A12&"_DGBE_0.3_0.2_0.5" -> Cap_TrX100_DGBE_0.3_0.2_0.5
A5: ='Indiv. Surfactant Key'!A12&"_DGBE_0.5_0.5" -> TrX100_DGBE_0.5_0.5
A6: ='Indiv. Surfactant Key'!A14&"_DGBE_0.5_0.5" -> Cap_DGBE_0.5_0.5
A7: G215_DGBE_0.5_0.5
A8: ='Indiv. Surfactant Key'!A14&"_G215_DGBE_0.3_0.2_0.5" -> Cap_G215_DGBE_0.3_0.2_0.5
A9: ='Indiv. Surfactant Key'!A14&"_"&'Indiv. Surfactant Key'!A12&"_DGBE_0.15_0.05_0.5" -> Cap_TrX100_DGBE_0.15_0.05_0.5
A10: ='Indiv. Surfactant Key'!A87&"_3" -> Buckeye 3%_3
A11: ='Indiv. Surfactant Key'!A88&"_6" -> RF6_6
A12: ='Indiv. Surfactant Key'!A11&"_1" -> SDS_1
A13: ='Indiv. Surfactant Key'!A14&"_"&'Indiv. Surfactant Key'!A12&"_DGBE_0.6_0.2_0.5" -> Cap_TrX100_DGBE_0.6_0.2_0.5
A14: ='Indiv. Surfactant Key'!A14&"_"&'Indiv. Surfactant Key'!A12&"_DGBE_0.6_0.4_0.5" -> Cap_TrX100_DGBE_0.6_0.4_0.5
A15: ='Indiv. Surfactant Key'!A14&"_"&'Indiv. Surfactant Key'!A12&"_DGBE_1.2_0.8_0.5" -> Cap_TrX100_DGBE_1.2_0.8_0.5
A16: ='Indiv. Surfactant Key'!A14&"_"&'Indiv. Surfactant Key'!A12&"_DGBE_0.3_0.2_1" -> Cap_TrX100_DGBE_0.3_0.2_1
A17: ='Indiv. Surfactant Key'!A85&"_G215_DGBE_0.14_0.09_0.5" -> Silsurf_G215_DGBE_0.14_0.09_0.5
A18: ='Indiv. Surfactant Key'!A84&"_G215_DGBE_0.3_0.2_0.5" -> Silphos_G215_DGBE_0.3_0.2_0.5
A19: ='Indiv. Surfactant Key'!A3&"_G215_DGBE_0.3_0.2_0.5" -> TMN6_G215_DGBE_0.3_0.2_0.5
A20: ='Indiv. Surfactant Key'!A4&"_G215_DGBE_0.03_0.02_0.5" -> T15-S-7_G215_DGBE_0.03_0.02_0.5
A21: ='Indiv. Surfactant Key'!A5&"_G215_DGBE_0.022_0.015_0.5" -> TrX45_G215_DGBE_0.022_0.015_0.5
A22: ='Indiv. Surfactant Key'!A6&"_G215_DGBE_0.04_0.027_0.5" -> TrX114_G215_DGBE_0.04_0.027_0.5
A23: ='Indiv. Surfactant Key'!A74&"_G215_DGBE_0.24_0.16_0.5" -> LinSucSulf_G215_DGBE_0.24_0.16_0.5
A24: ='Indiv. Surfactant Key'!A7&"_G215_DGBE_0.56_0.37_0.5" -> T4_G215_DGBE_0.56_0.37_0.5
A25: ='Indiv. Surfactant Key'!A75&"_G215_DGBE_0.13_0.09_0.5" -> TrCG-425_G215_DGBE_0.13_0.09_0.5
A26: ='Indiv. Surfactant Key'!A8&"_G215_DGBE_0.56_0.37_0.5" -> AlfSodSalt_G215_DGBE_0.56_0.37_0.5
A27: ='Indiv. Surfactant Key'!A76&"_G215_DGBE_0.52_0.35_0.5" -> AlphaFoam_G215_DGBE_0.52_0.35_0.5
A28: ='Indiv. Surfactant Key'!A9&"_G215_DGBE_0.068_0.045_0.5" -> Mys_G215_DGBE_0.068_0.045_0.5
A29: ='Indiv. Surfactant Key'!A77&"_G215_DGBE_0.3_0.2_0.5" -> D5575_G215_DGBE_0.3_0.2_0.5
A30: ='Indiv. Surfactant Key'!A78&"_G215_DGBE_0.3_0.2_0.5" -> D5244_G215_DGBE_0.3_0.2_0.5
A31: ='Indiv. Surfactant Key'!A79&"_G215_DGBE_0.12_0.08_0.5" -> D193_G215_DGBE_0.12_0.08_0.5
A32: ='Indiv. Surfactant Key'!A80&"_G215_DGBE_0.04_0.027_0.5" -> D501W_G215_DGBE_0.04_0.027_0.5
A33: ='Indiv. Surfactant Key'!A10&"_G215_DGBE_0.075_0.05_0.5" -> D502W_G215_DGBE_0.075_0.05_0.5
A34: ='Indiv. Surfactant Key'!A83&"_G215_DGBE_0.14_0.09_0.5" -> D5098_G215_DGBE_0.14_0.09_0.5
A35: ='Indiv. Surfactant Key'!A15&"_G215_DGBE_0.11_0.08_0.5" -> L77_G215_DGBE_0.11_0.08_0.5
A36: ='Indiv. Surfactant Key'!A86&"_G215_DGBE_0.06_0.04_0.5" -> D67_G215_DGBE_0.06_0.04_0.5
A37: ='Indiv. Surfactant Key'!A10&"_G225_DGBE_0.2_0.3_0.5" -> D502W_G225_DGBE_0.2_0.3_0.5
A38: ='Indiv. Surfactant Key'!A10&"_G225_0.2_0.3" -> D502W_G225_0.2_0.3
A39: ='Indiv. Surfactant Key'!A21&"_G225_DGBE_0.2_0.3_0.5" -> NRL_N10358-176_G225_DGBE_0.2_0.3_0.5
A40: ='Indiv. Surfactant Key'!A22&"_G225_DGBE_0.2_0.3_0.5" -> NRL_N10358-174_G225_DGBE_0.2_0.3_0.5
A41: G225_0.5
...

Sheet Measurement Information
A1: CMC- critical micelle concentration
A2: Surfactant will populate an air/water interface until it is saturated, after this concentration, excess surfactant will form micelles in solution rather than continuing to occupy surface
A3: Determined by measuring surface tension at various surfactant concentrations, above CMC, surface tension is independent of concentration, below CMC, surface tension is linearly dependent on concentration
A4: There are proposed relationships between sloped region of curve and gibbs free energy, so important to have CMC value as well as curved data
A6: CMC Concentrations | D6: wt% surfactant, this column of data is the concentration at which measurements were taken, different for each solution
A7: CMC Surface Tension | D7: mN/m, this column of data is the measured surface tension of solution at the corresponding concentration, different for each solution
A8: Calculated CMC | D8: wt% surfactant, my calculated value of CMC based on inflection point from data, may be able to calculcate from raw data, but is provided
A11: Formulation Surface Tension - surface tension is a measure of the force needed to travel from one interface to another, surface tension is specific to an air/liquid interface
A12: Measured via a DuNouy ring tensiometer at temperatures between 20-25C, these values are concentration specific and are notated with formulation names, units of mN/m
A14: Formulation Interfacial Tension - surface tension is a measure of the force needed to travel from one interface to another, interfacial tension is specific to a liquid/liquid interface which in our case is the fuel and foam solution
A15: Measured via a DuNouy ring tensiometer at temperatures between 20-25C, these values are concentration specific and are notated with formulation names, units of mN/m
A17: Formulation Fuel Transport - we assume that a mechanism of foam fire suppression is the ability of the foam to block the flow of fuel vapors from the fuel pool to the flame above,
A18: foams that reduce transport, may suppress a fire faster, we assume this mechanism is dependent on fuel type and temperature, as well as the surfactants in the foam layer
A19: We measure this outside of the flame environment using a flux chamber, foam is placed over heated fuel in a closed container, the head space above the foam is monitored via FTIR for heptane fuel vapors
A20: We report fuel transport through the foam as the fuel flux, correcting for FTIR ppm differences using the surface area of the fuel and the flow of gases used to sweep into the FTIR
A21: The fuel transport container is optically accesible to observe changes in foam height with time, which should also effect fuel transport rate, foams that degrade faster have a smaller physical barrier to travel through, the flux would be expectedly higher
A22: The transport degradation rate is used in a derived equation of Ficks 2nd Law to correct for differences in flux due to foam degradation and reports the effective diffusion coefficient (EDC value)
A23: The EDC value is the calculated value of heptane transport through a specified foam layer and is a potential value to compare extinction performance to; however, the raw flux and degradation curves may also be of value
A24: Degradation data in fuel transport experiment only recently collected, so minimal foam height profiles and EDC values reported
A26: Formulation Transport Time | D26: s, this column of data is the FTIR time stamp at which measurements were taken, different for each solution
A27: Fuel Transport PPM | D27: mol/cm2s, this column of data is the fuel flux through the foam layer, calculated from the FTIR ppm output, different for each solution
A28: Formulation Transport Deg Time | D28: min, this column of data is the time at which images of foam height were measured, can be used to plot foam height profile, in seconds, different for each solution
A29: Formulation Transport Deg Height | D29: cm, this column of data is the foam height measured at each time stamp during the transport test, in centimeters, different for each solution
A30: Formulation Flux Time for EDC | D30: don't fit the full transport profile to EDC values because of varying data points for each trial, consolidate down to 11 points for fitting, time of 11 points
A31: Flux Value for EDC | D31: associated fuel flux for 11 points used in fitting EDC vales
A32: EDC Value | D32: cm2/s, calculatd effective diffusion coefficient value using above profiles, first row is values, second row is r2 value of the fit to the flux data
D33: some fits <0.8, but still calculate values in line with replicate trials, your discretion as to what to weed out and what to keep
A35: Extinction results - measurement of the ability of a foam to extinguish a fire
A36: This metric is dependent on many variables - diameter of fuel pool, fuel, foam flow rate, and foam composition
A37: For comparing performance, critical that pool diameter, fuel, and flow rate be the same, all data presented is for a 19cm fuel pool diameter, but the fuel varies primarily between heptane and gasoline
A38: During fire extinction, we measure limited properties to better define the extinction event, these are described below
A39: Extinction curve is critical as it provides information on the limiting flow rate for rapid fire suppression, we include data at multiple foam flow rates to generate curves and typically do not present single extinction times
A40: A single trial is considered generation of the whole curve, we test the same foams at different times, generating full curves each time, Trials 1,2, and so on should each have complete curves
A41: Poor performing foams will have fewer foam flow rates analyzed as they were unable to extinguish a fire effectively
A43: Hept Fire Ext 19cm Foam Flow | D43: ml/min, foam flow rate is varied by varying an applied air flow rate to generate the foam. As the foam flow rate increases, more foam is deposited on the fire, fire is expected to go out faster
A44: Hept Fire Ext 19cm ER | D44: unitless, ER = expansion ratio, a foam property measurement of the water content of a foam, determined by dividing the volume of foam by its weight.
A45: Hept Fire Ext 19cm Spread | D45: s, time it takes for the foam to cover the fuel pool, poor performing foams can demonstrate "No Coverage"
A46: Hept Fire Ext 19cm Ext | D46: s, time for the foam to extinguish 100% of the fire, poor performing foams may have "No Extinction"
A48: Performance differences between fuels is expected, we therefore separate extinction based on fuel type and have a separate set of spreadsheets for gasoline fire extinction
A50: Gas Fire Ext 19cm Foam Flow | D50: ml/min, foam flow rate is varied by varying an applied air flow rate to generate the foam. As the foam flow rate increases, more foam is deposited on the fire, fire is expected to go out faster
...

Sheet CMC Concentrations
A1: Concentrations created for the calculation of CMC values, units are wt% total surfactant in aqueous solution, NaN values in place to create even-rowed columns
A3: ='Indiv. Surfactant Key'!A3 -> TMN6 | B3: ='Indiv. Surfactant Key'!A4 -> T15-S-7 | C3: ='Indiv. Surfactant Key'!A5 -> TrX45 | D3: ='Indiv. Surfactant Key'!A6 -> TrX114 | E3: ='Indiv. Surfactant Key'!A74 -> LinSucSulf | F3: ='Indiv. Surfactant Key'!A7 -> T4 | G3: ='Indiv. Surfactant Key'!A75 -> TrCG-425 | H3: ='Indiv. Surfactant Key'!A8 -> AlfSodSalt | I3: ='Indiv. Surfactant Key'!A76 -> AlphaFoam | J3: ='Indiv. Surfactant Key'!A77 -> D5575 | K3: ='Indiv. Surfactant Key'!A78 -> D5244 | L3: ='Indiv. Surfactant Key'!A79 -> D193 | M3: ='Indiv. Surfactant Key'!A80 -> D501W | N3: ='Indiv. Surfactant Key'!A81 -> D198 | O3: ='Indiv. Surfactant Key'!A82 -> D5604 | P3: ='Indiv. Surfactant Key'!A10 -> D502W | Q3: ='Indiv. Surfactant Key'!A83 -> D5098 | R3: ='Indiv. Surfactant Key'!A11 -> SDS | S3: ='Indiv. Surfactant Key'!A12 -> TrX100 | T3: ='Indiv. Surfactant Key'!A84 -> Silphos | U3: ='Indiv. Surfactant Key'!A85 -> Silsurf | V3: ='Indiv. Surfactant Key'!A13 -> CTAB | W3: ='Formulation Names Mix CMC Data'!A38 -> Cap_DGBE | X3: ='Indiv. Surfactant Key'!A14 -> Cap | Y3: ='Indiv. Surfactant Key'!A15 -> L77 | Z3: ='Indiv. Surfactant Key'!A16 -> PFOA | AA3: ='Indiv. Surfactant Key'!A86 -> D67 | AB3: ='Formulation Names Mix CMC Data'!A39 -> G225_DGBE | AC3: ='Formulation Names Mix CMC Data'!A40 -> G600_DGBE | AD3: ='Formulation Names Mix CMC Data'!A41 -> G215_DGBE | AE3: ='Formulation Names Mix CMC Data'!A42 -> Gel6185_DGBE | AF3: ='Indiv. Surfactant Key'!A17 -> NRL_N10358-107 | AG3: ='Indiv. Surfactant Key'!A18 -> NRL_N10358-106 | AH3: ='Indiv. Surfactant Key'!A19 -> NRL_N10358-135 | AI3: ='Indiv. Surfactant Key'!A20 -> NRL_N10477-12 | AJ3: ='Indiv. Surfactant Key'!A21 -> NRL_N10358-176 | AK3: ='Indiv. Surfactant Key'!A22 -> NRL_N10358-174 | AL3: ='Indiv. Surfactant Key'!A23 -> NRL_N10358-169 | AM3: ='Indiv. Surfactant Key'!A24 -> NRL_N10477-01 | AN3: ='Indiv. Surfactant Key'!A25 -> NRL_N10358-161 | AO3: ='Indiv. Surfactant Key'!A26 -> NRL_N10477-09 | AP3: ='Indiv. Surfactant Key'!A27 -> NRL_N10477-07 | AQ3: ='Indiv. Surfactant Key'!A28 -> NRL_N10477-03 | AR3: ='Indiv. Surfactant Key'!A29 -> NRL_N10477-05 | AS3: ='Indiv. Surfactant Key'!A30 -> Gel6185 | AT3: ='Indiv. Surfactant Key'!A31 -> G215 | AU3: ='Indiv. Surfactant Key'!A32 -> G225 | AV3: ='Formulation Names Mix CMC Data'!A4 -> TMN6_G215_3_2 | AW3: ='Formulation Names Mix CMC Data'!A5 -> T15-S-7_G215_3_2 | AX3: ='Formulation Names Mix CMC Data'!A6 -> TrX45_G215_3_2 | AY3: ='Formulation Names Mix CMC Data'!A7 -> TrX114_G215_3_2 | AZ3: ='Formulation Names Mix CMC Data'!A8 -> LinSucSulf_G215_3_2 | BA3: ='Formulation Names Mix CMC Data'!A9 -> T4_G215_3_2 | BB3: ='Formulation Names Mix CMC Data'!A10 -> TrCG-425_G215_3_2 | BC3: ='Formulation Names Mix CMC Data'!A11 -> AlfSodSalt_G215_3_2 | BD3: ='Formulation Names Mix CMC Data'!A12 -> AlphaFoam_G215_3_2 | BE3: ='Formulation Names Mix CMC Data'!A13 -> Mys_G215_3_2 | BF3: ='Formulation Names Mix CMC Data'!A14 -> D5575_G215_3_2 | BG3: ='Formulation Names Mix CMC Data'!A15 -> D5244_G215_3_2 | BH3: ='Formulation Names Mix CMC Data'!A16 -> D193_G215_3_2 | BI3: ='Formulation Names Mix CMC Data'!A17 -> D501W_G215_3_2 | BJ3: ='Formulation Names Mix CMC Data'!A18 -> D198_G215_3_2 | BK3: ='Formulation Names Mix CMC Data'!A19 -> D5604_G215_3_2 | BL3: ='Formulation Names Mix CMC Data'!A20 -> D502W_G215_3_2 | BM3: ='Formulation Names Mix CMC Data'!A21 -> D5098_G215_3_2 | BN3: ='Formulation Names Mix CMC Data'!A22 -> SDS_G215_3_2 | BO3: ='Formulation Names Mix CMC Data'!A23 -> TrX100_G215_3_2 | BP3: ='Formulation Names Mix CMC Data'!A24 -> Silphos_G215_3_2 | BQ3: ='Formulation Names Mix CMC Data'!A25 -> L77_G215_3_2 | BR3: ='Formulation Names Mix CMC Data'!A26 -> D502W_TrX100_3_2 | BS3: ='Formulation Names Mix CMC Data'!A27 -> D67_G215_3_2 | BT3: ='Formulation Names Mix CMC Data'!A28 -> D502W_G215_2_3 | BU3: ='Formulation Names Mix CMC Data'!A29 -> D502W_G225_2_3 | BV3: ='Formulation Names Mix CMC Data'!A30 -> D502W_G600_2_3 | BW3: ='Formulation Names Mix CMC Data'!A31 -> Gel6492.6_G215_3_2 | BX3: ='Formulation Names Mix CMC Data'!A32 -> T15-S-9_G215_3_2 | BY3: ='Formulation Names Mix CMC Data'!A33 -> T15-S-12_G215_3_2 | BZ3: ='Formulation Names Mix CMC Data'!A34 -> L77_G225_2_3 | CA3: ='Formulation Names Mix CMC Data'!A35 -> D67_G225_2_3 | CB3: ='Formulation Names Mix CMC Data'!A36 -> D502W_C6G2_1_1 | CC3: ='Formulation Names Mix CMC Data'!A37 -> Gel6185_G215_3_2 | CD3: ='Indiv. Surfactant Key'!A53 -> CL_MD2086-97 | CE3: ='Indiv. Surfactant Key'!A54 -> CL_MD2012-16 | CF3: ='Indiv. Surfactant Key'!A55 -> NRL_CB-1-123 | CG3: ='Formulation Names Mix CMC Data'!A43 -> CL_MD2086-97_G225_2_3 | CH3: ='Formulation Names Mix CMC Data'!A44 -> CL_MD2012-16_G225_2_3 | CI3: ='Formulation Names Mix CMC Data'!A45 -> NRL_CB-1-123_G225_2_3 | CJ3: ='Indiv. Surfactant Key'!A59 -> CL_MD2102-54 | CK3: ='Formulation Names Mix CMC Data'!A46 -> CL_MD2102-54_G225_2_3 | CL3: ='Indiv. Surfactant Key'!A64 -> NRL_LBII43 | CM3: ='Formulation Names Mix CMC Data'!A47 -> NRL_LBII43_G225_2_3 | CN3: ='Formulation Names Mix CMC Data'!A48 -> NRL_CB_DTBTS_SB_G225_2_3 | CO3: ='Formulation Names Mix CMC Data'!A49 -> NRL_N10478-233_G225_2_3 | CP3: ='Formulation Names Mix CMC Data'!A50 -> Cap_TrX100_3_2 | CQ3: ='Formulation Names Mix CMC Data'!A51 -> Cap_G225_3_2 | CR3: ='Formulation Names Mix CMC Data'!A52 -> CL_MD2062-57_G225_2_3 | CS3: ='Formulation Names Mix CMC Data'!A53 -> NRL_N10477-05_G225_2_3 | CT3: ='Formulation Names Mix CMC Data'!A54 -> D502W_C7G1_1_1 | CU3: ='Formulation Names Mix CMC Data'!A55 -> D502W_C7G1_1_1 | CV3: ='Formulation Names Mix CMC Data'!A56 -> D502W_C8G1_1_1 | CW3: ='Formulation Names Mix CMC Data'!A57 -> D502W_C9G2_1_1 | CX3: ='Formulation Names Mix CMC Data'!A58 -> D502W_C10G2_1_1 | CY3: ='Formulation Names Mix CMC Data'!A59 -> D502W_C12G2_1_1 | CZ3: ='Formulation Names Mix CMC Data'!A60 -> D502W_C8G2_1_1 | DA3: ='Formulation Names Mix CMC Data'!A61 -> D502W_iC8G2_1_1 | DB3: ='Formulation Names Mix CMC Data'!A62 -> D502W_Cymal_1_1 | DC3: ='Formulation Names Mix CMC Data'!A63 -> D502W_C8SG2_1_1 | DD3: ='Indiv. Surfactant Key'!A69 -> CL_MD2102-90 | DE3: ='Formulation Names Mix CMC Data'!A64 -> CL_MD2102-90_G225_2_3 | DF3: ='Indiv. Surfactant Key'!A71 -> CL_MD2102-118 | DG3: ='Formulation Names Mix CMC Data'!A65 -> CL_MD2102-118_G225_2_3 | DH3: ='Formulation Names Mix CMC Data'!A66 -> Cap_TrGR-5M_3_2 | DI3: ='Formulation Names Mix CMC Data'!A67 -> NRL_N10478-198_G225_1_5 | DJ3: ='Formulation Names Mix CMC Data'!A68 -> NRL_N10358-174_G225_2_3 | DK3: ='Formulation Names Mix CMC Data'!A69 -> NRL_N10358-176_G225_2_3 | DL3: ='Formulation Names Mix CMC Data'!A70 -> NRL_N10477-01_G225_2_3 | DM3: ='Formulation Names Mix CMC Data'!A71 -> NRL_N10477-03_G225_2_3 | DN3: ='Formulation Names Mix CMC Data'!A72 -> NRL_N10477-09_G225_2_3 | DO3: ='Formulation Names Mix CMC Data'!A73 -> NRL_N10477-07_G225_2_3 | DP3: ='Formulation Names Mix CMC Data'!A74 -> NRL_N10477-12_G225_2_3 | DQ3: ='Indiv. Surfactant Key'!A70 -> CL_MD2102-112 | DR3: ='Formulation Names Mix CMC Data'!A76 -> CL_MD2102-112_G225_2_3 | DS3: ='Formulation Names Mix CMC Data'!A77 -> CL_MD2062-124_G225_1_4.6 | DT3: ='Formulation Names Mix CMC Data'!A78 -> NRL_N10477-189_G225_1_6 | DU3: ='Indiv. Surfactant Key'!A72 -> NRL_CB-1-192 | DV3: ='Formulation Names Mix CMC Data'!A80 -> NRL_CB-1-192_G225_2_3
A4: 2 | B4: 2 | C4: 2 | D4: 2 | E4: 2 | F4: 2 | G4: 2 | H4: 2 | I4: 2 | J4: 2 | K4: 2 | L4: 2 | M4: 2 | N4: 2 | O4: 2 | P4: 2 | Q4: 2 | R4: 2 | S4: 2 | T4: 2 | U4: 2 | V4: 2 | W4: 2 | X4: 2 | Y4: 2 | Z4: 2 | AA4: 2 | AB4: 2 | AC4: 2 | AD4: 2 | AE4: 2 | AF4: 2 | AG4: 2 | AH4: 2 | AI4: 2 | AJ4: 2 | AK4: 2 | AL4: 2 | AM4: 2 | AN4: 2 | AO4: 2 | AP4: 2 | AQ4: 2 | AR4: 2 | AS4: 2 | AT4: 2 | AU4: 2 | AV4: 2 | AW4: 2 | AX4: 2 | AY4: 2 | AZ4: 2 | BA4: 2 | BB4: 2 | BC4: 2 | BD4: 2 | BE4: 2 | BF4: 2 | BG4: 2 | BH4: 2 | BI4: 2 | BJ4: 2 | BK4: 2 | BL4: 2 | BM4: 2 | BN4: 2 | BO4: 2 | BP4: 2 | BQ4: 2 | BR4: 2 | BS4: 2 | BT4: 2 | BU4: 2 | BV4: 2 | BW4: 2 | BX4: 2 | BY4: 2 | BZ4: 2 | CA4: 2 | CB4: 5 | CC4: 2 | CD4: 2 | CE4: 2 | CF4: 2 | CG4: 2 | CH4: 1 | CI4: 2 | CJ4: 2 | CK4: 2 | CL4: 1 | CM4: 1 | CN4: 0.05 | CO4: 0.5 | CP4: 2 | CQ4: 0.5 | CR4: 2 | CS4: 2 | CT4: 2 | CU4: 2 | CV4: 2 | CW4: 2 | CX4: 2 | CY4: 2 | CZ4: 2 | DA4: 2 | DB4: 2 | DC4: 2 | DD4: 1 | DE4: 1 | DF4: 0.5 | DG4: 0.5 | DH4: =2 -> 2 | DI4: 1 | DJ4: =2 -> 2 | DK4: =2 -> 2 | DL4: =2 -> 2 | DM4: 1 | DN4: 2 | DO4: 2 | DP4: 2 | DQ4: 0.5 | DR4: 0.5 | DS4: 0.365 | DT4: 0.35 | DU4: 1 | DV4: 1
A5: 1 | B5: 1 | C5: 1 | D5: 1 | E5: 1 | F5: 1 | G5: 1 | H5: 1 | I5: 1 | J5: 1 | K5: 1 | L5: 1 | M5: 1 | N5: 1 | O5: 1 | P5: 1 | Q5: 1 | R5: 1 | S5: 1 | T5: 1 | U5: 1 | V5: 1 | W5: 1 | X5: 0.0625 | Y5: 1 | Z5: 1 | AA5: 0.0625 | AB5: 1 | AC5: 0.0625 | AD5: 1 | AE5: 0.0625 | AF5: 1 | AG5: 1 | AH5: 1 | AI5: 0.0625 | AJ5: 0.0625 | AK5: 1 | AL5: 0.0625 | AM5: 0.0625 | AN5: 0.0625 | AO5: 0.0625 | AP5: 0.0625 | AQ5: 0.0625 | AR5: 0.0625 | AS5: 0.0625 | AT5: 1 | AU5: 1 | AV5: 1 | AW5: 1 | AX5: 1 | AY5: 1 | AZ5: 1 | BA5: 1 | BB5: 1 | BC5: 1 | BD5: 1 | BE5: 1 | BF5: 1 | BG5: 1 | BH5: 1 | BI5: 1 | BJ5: 1 | BK5: 1 | BL5: 1 | BM5: 1 | BN5: 1 | BO5: 1 | BP5: 1 | BQ5: 1 | BR5: 0.0625 | BS5: 0.0625 | BT5: 0.0625 | BU5: 0.0625 | BV5: 0.0625 | BW5: 0.0625 | BX5: 0.0625 | BY5: 0.0625 | BZ5: 0.0625 | CA5: 0.0625 | CB5: 0.15625 | CC5: 0.0625 | CD5: 1 | CE5: 0.25 | CF5: 1 | CG5: 1 | CH5: 0.5 | CI5: 0.5 | CJ5: 0.25 | CK5: 1 | CL5: 0.125 | CM5: 0.125 | CN5: =CN4/2 -> 0.025 | CO5: 0.0625 | CP5: 0.0625 | CQ5: 0.0625 | CR5: 1 | CS5: 1 | CT5: 1 | CU5: 1 | CV5: 1 | CW5: 1 | CX5: 1 | CY5: 1 | CZ5: 1 | DA5: 1 | DB5: 1 | DC5: 1 | DD5: 0.5 | DE5: 0.25 | DF5: 0.0625 | DG5: 0.0625 | DH5: =0.0625 -> 0.0625 | DI5: =DI4/2 -> 0.5 | DJ5: =1 -> 1 | DK5: =0.0625 -> 0.0625 | DL5: =0.5 -> 0.5 | DM5: 0.0625 | DN5: 0.0625 | DO5: 0.0625 | DP5: 0.0625 | DQ5: 0.0625 | DR5: 0.0625 | DS5: =DS4/2 -> 0.1825 | DT5: =DT4/2 -> 0.175 | DU5: 0.5 | DV5: 0.5
A6: 0.5 | B6: 0.5 | C6: 0.5 | D6: 0.5 | E6: 0.5 | F6: 0.5 | G6: 0.5 | H6: 0.5 | I6: 0.5 | J6: 0.5 | K6: 0.5 | L6: 0.5 | M6: 0.5 | N6: 0.5 | O6: 0.5 | P6: 0.5 | Q6: 0.5 | R6: 0.5 | S6: 0.5 | T6: 0.5 | U6: 0.5 | V6: 0.5 | W6: 0.5 | X6: 0.03125 | Y6: 0.5 | Z6: 0.5 | AA6: 0.03125 | AB6: 0.5 | AC6: 0.03125 | AD6: 0.5 | AE6: 0.03125 | AF6: 0.5 | AG6: 0.5 | AH6: 0.5 | AI6: 0.03125 | AJ6: 0.03125 | AK6: 0.0625 | AL6: 0.03125 | AM6: 0.03125 | AN6: 0.03125 | AO6: 0.03125 | AP6: 0.03125 | AQ6: 0.03125 | AR6: 0.03125 | AS6: 0.03125 | AT6: 0.5 | AU6: 0.5 | AV6: 0.5 | AW6: 0.5 | AX6: 0.5 | AY6: 0.5 | AZ6: 0.5 | BA6: 0.5 | BB6: 0.5 | BC6: 0.5 | BD6: 0.5 | BE6: 0.5 | BF6: 0.5 | BG6: 0.5 | BH6: 0.5 | BI6: 0.5 | BJ6: 0.5 | BK6: 0.5 | BL6: 0.5 | BM6: 0.5 | BN6: 0.5 | BO6: 0.5 | BP6: 0.5 | BQ6: 0.5 | BR6: 0.03125 | BS6: 0.03125 | BT6: 0.03125 | BU6: 0.03125 | BV6: 0.03125 | BW6: 0.03125 | BX6: 0.03125 | BY6: 0.03125 | BZ6: 0.03125 | CA6: 0.03125 | CB6: 0.0390625 | CC6: 0.03125 | CD6: 0.0625 | CE6: 0.125 | CF6: 0.5 | CG6: 0.5 | CH6: 0.25 | CI6: 0.25 | CJ6: 0.125 | CK6: 0.125 | CL6: 0.0625 | CM6: 0.0625 | CN6: =CN5/2 -> 0.0125 | CO6: 0.03125 | CP6: =CP5/2 -> 0.03125 | CQ6: =CQ5/2 -> 0.03125 | CR6: 0.5 | CS6: 0.5 | CT6: 0.0625 | CU6: 0.0625 | CV6: 0.0625 | CW6: 0.0625 | CX6: 0.0625 | CY6: 0.0625 | CZ6: 0.0625 | DA6: 0.0625 | DB6: 0.0625 | DC6: 0.0625 | DD6: 0.25 | DE6: 0.125 | DF6: 0.03125 | DG6: 0.03125 | DH6: =DH5/2 -> 0.03125 | DI6: 0.0625 | DJ6: =0.0625 -> 0.0625 | DK6: =DK5/2 -> 0.03125 | DL6: =0.0625 -> 0.0625 | DM6: =DM5/2 -> 0.03125 | DN6: =DN5/2 -> 0.03125 | DO6: =DO5/2 -> 0.03125 | DP6: =DP5/2 -> 0.03125 | DQ6: 0.03125 | DR6: 0.03125 | DS6: =DS5/2 -> 0.09125 | DT6: =DT5/2 -> 0.0875 | DU6: 0.25 | DV6: 0.25
A7: 0.25 | B7: 0.25 | C7: 0.25 | D7: 0.25 | E7: 0.25 | F7: 0.25 | G7: 0.25 | H7: 0.25 | I7: 0.25 | J7: 0.25 | K7: 0.25 | L7: 0.25 | M7: 0.25 | N7: 0.25 | O7: 0.25 | P7: 0.25 | Q7: 0.25 | R7: 0.25 | S7: 0.25 | T7: 0.25 | U7: 0.25 | V7: 0.25 | W7: 0.25 | X7: 0.015625 | Y7: 0.25 | Z7: 0.25 | AA7: 0.015625 | AB7: 0.25 | AC7: 0.015625 | AD7: 0.25 | AE7: 0.015625 | AF7: 0.25 | AG7: 0.25 | AH7: 0.25 | AI7: 0.015625 | AJ7: 0.015625 | AK7: 0.03125 | AL7: 0.015625 | AM7: 0.015625 | AN7: 0.015625 | AO7: 0.015625 | AP7: 0.015625 | AQ7: 0.015625 | AR7: 0.015625 | AS7: 0.015625 | AT7: 0.25 | AU7: 0.25 | AV7: 0.25 | AW7: 0.25 | AX7: 0.25 | AY7: 0.25 | AZ7: 0.25 | BA7: 0.25 | BB7: 0.25 | BC7: 0.25 | BD7: 0.25 | BE7: 0.25 | BF7: 0.25 | BG7: 0.25 | BH7: 0.25 | BI7: 0.25 | BJ7: 0.25 | BK7: 0.25 | BL7: 0.25 | BM7: 0.25 | BN7: 0.25 | BO7: 0.25 | BP7: 0.25 | BQ7: 0.25 | BR7: 0.015625 | BS7: 0.015625 | BT7: 0.015625 | BU7: 0.015625 | BV7: 0.015625 | BW7: 0.015625 | BX7: 0.015625 | BY7: 0.015625 | BZ7: 0.015625 | CA7: 0.015625 | CB7: 0.01953125 | CC7: 0.015625 | CD7: 0.03125 | CE7: 0.0625 | CF7: 0.25 | CG7: 0.0625 | CH7: 0.125 | CI7: 0.125 | CJ7: 0.0625 | CK7: 0.0625 | CL7: 0.03125 | CM7: 0.03125 | CN7: =CN6/2 -> 0.00625 | CO7: 0.015625 | CP7: =CP6/2 -> 0.015625 | CQ7: =CQ6/2 -> 0.015625 | CR7: =CR6/2 -> 0.25 | CS7: 0.25 | CT7: =CT6/2 -> 0.03125 | CU7: =CU6/2 -> 0.03125 | CV7: =CV6/2 -> 0.03125 | CW7: =CW6/2 -> 0.03125 | CX7: =CX6/2 -> 0.03125 | CY7: =CY6/2 -> 0.03125 | CZ7: =CZ6/2 -> 0.03125 | DA7: =DA6/2 -> 0.03125 | ... DC7: =DC6/2 -> 0.03125 | DD7: 0.125 | DE7: 0.0625 | DF7: 0.015625 | DG7: 0.015625 | DH7: =DH6/2 -> 0.015625 | DI7: =DI6/2 -> 0.03125 | DJ7: =DJ6/2 -> 0.03125 | DK7: =DK6/2 -> 0.015625 | DL7: =DL6/2 -> 0.03125 | DM7: =DM6/2 -> 0.015625 | DN7: =DN6/2 -> 0.015625 | DO7: =DO6/2 -> 0.015625 | DP7: =DP6/2 -> 0.015625 | DQ7: 0.015625 | DR7: 0.015625 | DS7: =DS6/2 -> 0.045625 | DT7: =DT6/2 -> 0.04375 | DU7: 0.125 | DV7: 0.125
A8: 0.125 | B8: 0.125 | C8: 0.125 | D8: 0.125 | E8: 0.125 | F8: 0.125 | G8: 0.125 | H8: 0.125 | I8: 0.125 | J8: 0.125 | K8: 0.125 | L8: 0.125 | M8: 0.125 | N8: 0.125 | O8: 0.125 | P8: 0.125 | Q8: 0.125 | R8: 0.125 | S8: 0.125 | T8: 0.125 | U8: 0.125 | V8: 0.125 | W8: 0.125 | X8: 0.0078125 | Y8: 0.125 | Z8: 0.125 | AA8: 0.0078125 | AB8: 0.125 | AC8: 0.0078125 | AD8: 0.125 | AE8: 0.0078125 | AF8: 0.125 | AG8: 0.125 | AH8: 0.125 | AI8: 0.0078125 | AJ8: 0.0078125 | AK8: 0.015625 | AL8: 0.0078125 | AM8: 0.0078125 | AN8: 0.0078125 | AO8: 0.0078125 | AP8: 0.0078125 | AQ8: 0.0078125 | AR8: 0.0078125 | AS8: 0.0078125 | AT8: 0.125 | AU8: 0.125 | AV8: 0.125 | AW8: 0.125 | AX8: 0.125 | AY8: 0.125 | AZ8: 0.125 | BA8: 0.125 | BB8: 0.125 | BC8: 0.125 | BD8: 0.125 | BE8: 0.125 | BF8: 0.125 | BG8: 0.125 | BH8: 0.125 | BI8: 0.125 | BJ8: 0.125 | BK8: 0.125 | BL8: 0.125 | BM8: 0.125 | BN8: 0.125 | BO8: 0.125 | BP8: 0.125 | BQ8: 0.125 | BR8: 0.0078125 | BS8: 0.0078125 | BT8: 0.0078125 | BU8: 0.0078125 | BV8: 0.0078125 | BW8: 0.0078125 | BX8: 0.0078125 | BY8: 0.0078125 | BZ8: 0.0078125 | CA8: 0.0078125 | CB8: 0.009765625 | CC8: 0.0078125 | CD8: 0.015625 | CE8: 0.03125 | CF8: 0.125 | CG8: 0.03125 | CH8: 0.0625 | CI8: 0.0625 | CJ8: 0.03125 | CK8: 0.03125 | CL8: 0.015625 | CM8: 0.015625 | CN8: =CN7/2 -> 0.003125 | CO8: 0.0078125 | CP8: =CP7/2 -> 0.0078125 | CQ8: =CQ7/2 -> 0.0078125 | CR8: =CR7/2 -> 0.125 | CS8: =CS7/2 -> 0.125 | CT8: =CT7/2 -> 0.015625 | CU8: =CU7/2 -> 0.015625 | CV8: =CV7/2 -> 0.015625 | CW8: =CW7/2 -> 0.015625 | ... DC8: =DC7/2 -> 0.015625 | DD8: 0.0625 | DE8: 0.03125 | DF8: 0.0078125 | DG8: 0.0078125 | DH8: =DH7/2 -> 0.0078125 | DI8: =DI7/2 -> 0.015625 | DJ8: =DJ7/2 -> 0.015625 | DK8: =DK7/2 -> 0.0078125 | DL8: =DL7/2 -> 0.015625 | DM8: =DM7/2 -> 0.0078125 | DN8: =DN7/2 -> 0.0078125 | DO8: =DO7/2 -> 0.0078125 | DP8: =DP7/2 -> 0.0078125 | DQ8: 0.0078125 | DR8: 0.0078125 | DS8: =DS7/2 -> 0.0228125 | DT8: =DT7/2 -> 0.021875 | DU8: 0.0625 | DV8: 0.0625
A9: 0.0625 | B9: 0.0625 | C9: 0.0625 | D9: 0.0625 | E9: 0.0625 | F9: 0.0625 | G9: 0.0625 | H9: 0.0625 | I9: 0.0625 | J9: 0.0625 | K9: 0.0625 | L9: 0.0625 | M9: 0.0625 | N9: 0.0625 | O9: 0.0625 | P9: 0.0625 | Q9: 0.0625 | R9: 0.0625 | S9: 0.0625 | T9: 0.0625 | U9: 0.0625 | V9: 0.0625 | W9: 0.0625 | X9: 0.00390625 | Y9: 0.0625 | Z9: 0.0625 | AA9: 0.00390625 | AB9: 0.0625 | AC9: 0.00390625 | AD9: 0.0625 | AE9: 0.00390625 | AF9: 0.0625 | AG9: 0.0625 | AH9: 0.0625 | AI9: 0.00390625 | AJ9: 0.00390625 | AK9: 0.0078125 | AL9: 0.00390625 | AM9: 0.00390625 | AN9: 0.00390625 | AO9: 0.00390625 | AP9: 0.00390625 | AQ9: 0.00390625 | AR9: 0.00390625 | AS9: 0.00390625 | AT9: 0.0625 | AU9: 0.0625 | AV9: 0.0625 | AW9: 0.0625 | AX9: 0.0625 | AY9: 0.0625 | AZ9: 0.0625 | BA9: 0.0625 | BB9: 0.0625 | BC9: 0.0625 | BD9: 0.0625 | BE9: 0.0625 | BF9: 0.0625 | BG9: 0.0625 | BH9: 0.0625 | BI9: 0.0625 | BJ9: 0.0625 | BK9: 0.0625 | BL9: 0.0625 | BM9: 0.0625 | BN9: 0.0625 | BO9: 0.0625 | BP9: 0.0625 | BQ9: 0.0625 | BR9: 0.00390625 | BS9: 0.00390625 | BT9: 0.00390625 | BU9: 0.00390625 | BV9: 0.00390625 | BW9: 0.00390625 | BX9: 0.00390625 | BY9: 0.00390625 | BZ9: 0.00390625 | CA9: 0.00390625 | CB9: 0.0048828125 | CC9: 0.00390625 | CD9: 0.0078125 | CE9: NaN | CF9: 0.0625 | CG9: 0.015625 | CH9: 0.03125 | CI9: 0.03125 | CJ9: 0.015625 | CK9: 0.015625 | CL9: 0.0078125 | CM9: 0.0078125 | CN9: =CN8/2 -> 0.0015625 | CO9: 0.00390625 | CP9: =CP8/2 -> 0.00390625 | CQ9: =CQ8/2 -> 0.00390625 | CR9: 0.0625 | CS9: =CS8/2 -> 0.0625 | CT9: =CT8/2 -> 0.0078125 | CU9: =CU8/2 -> 0.0078125 | CV9: =CV8/2 -> 0.0078125 | CW9: =CW8/2 -> 0.0078125 | CX9: =CX8/2 -> 0.0078125 | CY9: =CY8/2 -> 0.0078125 | CZ9: =CZ8/2 -> 0.0078125 | ... DC9: =DC8/2 -> 0.0078125 | DD9: 0.03125 | DE9: 0.015625 | DF9: 0.00390625 | DG9: 0.00390625 | DH9: =DH8/2 -> 0.00390625 | DI9: =DI8/2 -> 0.0078125 | DJ9: =DJ8/2 -> 0.0078125 | DK9: =DK8/2 -> 0.00390625 | DL9: =DL8/2 -> 0.0078125 | DM9: =DM8/2 -> 0.00390625 | DN9: =DN8/2 -> 0.00390625 | DO9: =DO8/2 -> 0.00390625 | DP9: =DP8/2 -> 0.00390625 | DQ9: 0.00390625 | DR9: 0.00390625 | DS9: =DS8/2 -> 0.01140625 | DT9: =DT8/2 -> 0.0109375 | DU9: 0.03125 | DV9: 0.03125
A10: 0.03125 | B10: 0.03125 | C10: 0.03125 | D10: 0.03125 | E10: 0.03125 | F10: 0.03125 | G10: 0.03125 | H10: NaN | I10: NaN | J10: 0.03125 | K10: 0.03125 | L10: 0.03125 | M10: 0.03125 | N10: 0.03125 | O10: 0.03125 | P10: 0.03125 | Q10: 0.03125 | R10: 0.03125 | S10: 0.03125 | T10: 0.03125 | U10: 0.03125 | V10: 0.03125 | W10: 0.03125 | X10: 0.001953125 | Y10: 0.03125 | Z10: 0.03125 | AA10: 0.001953125 | AB10: 0.03125 | AC10: 0.001953125 | AD10: 0.03125 | AE10: 0.001953125 | AF10: 0.03125 | AG10: 0.03125 | AH10: 0.03125 | AI10: 0.001953125 | AJ10: 0.001953125 | AK10: 0.00390625 | AL10: 0.001953125 | AM10: 0.001953125 | AN10: 0.001953125 | AO10: 0.001953125 | AP10: 0.001953125 | AQ10: 0.001953125 | AR10: 0.001953125 | AS10: 0.001953125 | AT10: 0.03125 | AU10: 0.03125 | AV10: 0.03125 | AW10: 0.03125 | AX10: 0.03125 | AY10: 0.03125 | AZ10: 0.03125 | BA10: 0.03125 | BB10: 0.03125 | BC10: 0.03125 | BD10: 0.03125 | BE10: 0.03125 | BF10: 0.03125 | BG10: 0.03125 | BH10: 0.03125 | BI10: 0.03125 | BJ10: 0.03125 | BK10: 0.03125 | BL10: 0.03125 | BM10: 0.03125 | BN10: 0.03125 | BO10: 0.03125 | BP10: 0.03125 | BQ10: 0.03125 | BR10: 0.001953125 | BS10: 0.001953125 | BT10: 0.001953125 | BU10: 0.001953125 | BV10: 0.001953125 | BW10: 0.001953125 | BX10: 0.001953125 | BY10: 0.001953125 | BZ10: 0.001953125 | CA10: 0.001953125 | CB10: 0.0024414062 | CC10: 0.001953125 | CD10: 0.00390625 | CE10: NaN | CF10: 0.03125 | CG10: 0.0078125 | CH10: 0.015625 | CI10: NaN | CJ10: 0.0078125 | CK10: 0.0078125 | CL10: 0.00390625 | CM10: 0.00390625 | CN10: NaN | CO10: 0.001953125 | CP10: =CP9/2 -> 0.001953125 | CQ10: =CQ9/2 -> 0.001953125 | CR10: =CR9/2 -> 0.03125 | CS10: =CS9/2 -> 0.03125 | CT10: =CT9/2 -> 0.00390625 | CU10: =CU9/2 -> 0.00390625 | CV10: =CV9/2 -> 0.00390625 | CW10: =CW9/2 -> 0.00390625 | ... DC10: =DC9/2 -> 0.00390625 | DD10: 0.015625 | DE10: 0.0078125 | DF10: 0.001953125 | DG10: 0.001953125 | DH10: =DH9/2 -> 0.001953125 | DI10: =DI9/2 -> 0.00390625 | DJ10: =DJ9/2 -> 0.00390625 | DK10: =DK9/2 -> 0.001953125 | DL10: =DL9/2 -> 0.00390625 | DM10: =DM9/2 -> 0.001953125 | DN10: =DN9/2 -> 0.001953125 | DO10: =DO9/2 -> 0.001953125 | DP10: =DP9/2 -> 0.001953125 | DQ10: 0.001953125 | DR10: 0.001953125 | DS10: =DS9/2 -> 0.005703125 | DT10: =DT9/2 -> 0.00546875 | DU10: 0.015625 | DV10: 0.015625
